2019-07-11 17:21:02,993 - ERROR - logger.py[:74] - 测试失败
Traceback (most recent call last):
  File "C:\Users\admin\PycharmProjects\May\testcases\test_login.py", line 31, in test_login
    self.assertTrue(My_assertion.my_assert(case.expected,resp_str))
  File "C:\Python34\lib\unittest\case.py", line 657, in assertTrue
    raise self.failureException(msg)
AssertionError: False is not true
2019-07-11 17:21:03,250 - ERROR - logger.py[:74] - 测试失败
Traceback (most recent call last):
  File "C:\Users\admin\PycharmProjects\May\testcases\test_login.py", line 31, in test_login
    self.assertTrue(My_assertion.my_assert(case.expected,resp_str))
  File "C:\Python34\lib\unittest\case.py", line 657, in assertTrue
    raise self.failureException(msg)
AssertionError: False is not true
2019-07-11 17:27:23,290 - ERROR - logger.py[:74] - 测试失败
Traceback (most recent call last):
  File "C:\Users\admin\PycharmProjects\May\testcases\test_login.py", line 31, in test_login
    self.assertTrue(My_assertion.my_assert(case.expected,resp_str))
  File "C:\Python34\lib\unittest\case.py", line 657, in assertTrue
    raise self.failureException(msg)
AssertionError: False is not true
2019-07-11 17:27:23,374 - ERROR - logger.py[:74] - 测试失败
Traceback (most recent call last):
  File "C:\Users\admin\PycharmProjects\May\testcases\test_login.py", line 31, in test_login
    self.assertTrue(My_assertion.my_assert(case.expected,resp_str))
  File "C:\Python34\lib\unittest\case.py", line 657, in assertTrue
    raise self.failureException(msg)
AssertionError: False is not true
2019-07-11 17:28:18,987 - ERROR - logger.py[:74] - 测试失败
Traceback (most recent call last):
  File "C:\Users\admin\PycharmProjects\May\testcases\test_login.py", line 31, in test_login
    self.assertTrue(My_assertion.my_assert(case.expected,resp_str))
  File "C:\Python34\lib\unittest\case.py", line 657, in assertTrue
    raise self.failureException(msg)
AssertionError: False is not true
2019-07-11 17:28:19,098 - ERROR - logger.py[:74] - 测试失败
Traceback (most recent call last):
  File "C:\Users\admin\PycharmProjects\May\testcases\test_login.py", line 31, in test_login
    self.assertTrue(My_assertion.my_assert(case.expected,resp_str))
  File "C:\Python34\lib\unittest\case.py", line 657, in assertTrue
    raise self.failureException(msg)
AssertionError: False is not true
